2024-01-19 02:48:52,798 : INFO : Start of Training
2024-01-19 02:48:52,804 : INFO : Run_id: 2024-01-19_024852_529388646
2024-01-19 02:48:52,806 : INFO : Start of Data Load, validation and transformation...
2024-01-19 02:48:52,814 : INFO : Start of Archiving Old Rejected Files...
2024-01-19 02:48:52,814 : INFO : End of Archiving Old Rejected Files...
2024-01-19 02:48:52,814 : INFO : Start of Archiving Old Validated Files...
2024-01-19 02:48:52,821 : INFO : End of Archiving Old Validated Files...
2024-01-19 02:48:52,821 : INFO : Start of Archiving Old Processed Files...
2024-01-19 02:48:52,821 : INFO : End of Archiving Old Processed Files...
2024-01-19 02:48:52,821 : INFO : Start of Archiving Old Result Files...
2024-01-19 02:48:52,821 : INFO : End of Archiving Old Result Files...
2024-01-19 02:48:52,821 : INFO : Start of Reading values From Schema...
2024-01-19 02:48:52,821 : ERROR : KeyError raised while Reading values From Schema
Traceback (most recent call last):
  File "/home/draeghonvm/Projects/Supervised_ML_Project/apps/ingestion/load_validate.py", line 54, in values_from_schema
    f.close()
              
KeyError: 'colName'
2024-01-19 02:48:52,821 : ERROR : Unsuccessful End of Training
Traceback (most recent call last):
  File "/home/draeghonvm/Projects/Supervised_ML_Project/apps/ingestion/load_validate.py", line 54, in values_from_schema
    f.close()
              
KeyError: 'colName'

During handling of the above exception, another exception occurred:

Traceback (most recent call last):
  File "/home/draeghonvm/Projects/Supervised_ML_Project/apps/ingestion/load_validate.py", line 276, in validate_trainset
    #extracting values from training schema
                                      ^^^^^^
  File "/home/draeghonvm/Projects/Supervised_ML_Project/apps/ingestion/load_validate.py", line 62, in values_from_schema
    self.logger.exception('KeyError raised while Reading values From Schema')
    ^^^^^^^^^^^^^^
KeyError

During handling of the above exception, another exception occurred:

Traceback (most recent call last):
  File "/home/draeghonvm/Projects/Supervised_ML_Project/apps/training/train_model.py", line 58, in training_model
    self.loadValidate.validate_trainset()
  File "/home/draeghonvm/Projects/Supervised_ML_Project/apps/ingestion/load_validate.py", line 293, in validate_trainset
    except Exception:
        ^^^^^^^^^^^^^^
TypeError: 'Logger' object is not callable
