2024-01-19 03:20:33,962 : INFO : Start of Training
2024-01-19 03:20:33,962 : INFO : Run_id: 2024-01-19_032033_492634092
2024-01-19 03:20:33,962 : INFO : Start of Data Load, validation and transformation...
2024-01-19 03:20:33,962 : INFO : Start of Archiving Old Rejected Files...
2024-01-19 03:20:33,962 : INFO : End of Archiving Old Rejected Files...
2024-01-19 03:20:33,962 : INFO : Start of Archiving Old Validated Files...
2024-01-19 03:20:33,962 : INFO : End of Archiving Old Validated Files...
2024-01-19 03:20:33,962 : INFO : Start of Archiving Old Processed Files...
2024-01-19 03:20:33,962 : INFO : End of Archiving Old Processed Files...
2024-01-19 03:20:33,962 : INFO : Start of Archiving Old Result Files...
2024-01-19 03:20:33,962 : INFO : End of Archiving Old Result Files...
2024-01-19 03:20:33,962 : INFO : Start of Reading values From Schema...
2024-01-19 03:20:33,962 : INFO : End of Reading values From Schema...
2024-01-19 03:20:33,962 : INFO : Start of Validating Column Length...
2024-01-19 03:20:33,977 : INFO : End of Validating column Length
2024-01-19 03:20:33,977 : INFO : Start of Validating Missing Values...
2024-01-19 03:20:33,992 : INFO : End of Validating Missing Values
2024-01-19 03:20:33,992 : INFO : Start of Replacing Missing Values with NULL...
2024-01-19 03:20:34,051 : INFO : hr_employee_churn_data.csv: File Transformed successfully!!
2024-01-19 03:20:34,051 : INFO : End of Replacing Missing Values with NULL...
2024-01-19 03:20:34,051 : INFO : Start of Creating Table...
2024-01-19 03:20:34,052 : INFO : Opened training database successfully
2024-01-19 03:20:34,054 : INFO : Tables created successfully
2024-01-19 03:20:34,054 : INFO : Closed training database successfully
2024-01-19 03:20:34,054 : INFO : End of Creating Table...
2024-01-19 03:20:34,054 : INFO : Opened training database successfully
2024-01-19 03:20:34,054 : INFO : Start of Inserting Data into Table...
2024-01-19 03:26:21,737 : INFO : End of Inserting Data into Table...
2024-01-19 03:26:21,737 : INFO : Start of Exporting Data into CSV...
2024-01-19 03:26:21,737 : INFO : Opened training database successfully
2024-01-19 03:26:21,800 : INFO : End of Exporting Data into CSV...
2024-01-19 03:26:21,802 : INFO : Start of Moving Processed Files...
2024-01-19 03:26:21,802 : INFO : Moved the already processed file hr_employee_churn_data.csv
2024-01-19 03:26:21,802 : INFO : End of Moving Processed Files...
2024-01-19 03:26:21,802 : INFO : End of Data Load, validation and transformation
2024-01-19 03:26:21,802 : INFO : Start of Preprocessing...
2024-01-19 03:26:21,802 : INFO : Start of Reading dataset...
2024-01-19 03:26:21,813 : INFO : End of reading dataset...
2024-01-19 03:26:21,813 : INFO : Start of Droping columns...
2024-01-19 03:26:21,887 : INFO : End of Droping columns...
2024-01-19 03:26:21,887 : INFO : Start of feature encoding...
2024-01-19 03:26:21,907 : INFO : End of feature encoding...
2024-01-19 03:26:21,908 : INFO : Start of Droping columns...
2024-01-19 03:26:21,920 : INFO : End of Droping columns...
2024-01-19 03:26:21,920 : INFO : Start of finding missing values...
2024-01-19 03:26:21,923 : INFO : Start of finding missing values...
2024-01-19 03:26:21,923 : INFO : Start of Imputing missing values...
2024-01-19 03:26:21,983 : INFO : End of Imputing missing values...
2024-01-19 03:26:21,984 : INFO : Start of splitting features and label...
2024-01-19 03:26:21,984 : INFO : End of splitting features and label...
2024-01-19 03:26:21,984 : INFO : End of Preprocessing...
2024-01-19 03:26:21,984 : INFO : Start of elbow plotting...
2024-01-19 03:26:38,803 : INFO : The optimum number of clusters is: 3
2024-01-19 03:26:38,804 : INFO : End of elbow plotting...
2024-01-19 03:26:38,804 : ERROR : Unsuccessful End of Training
Traceback (most recent call last):
  File "/home/draeghonvm/Projects/Supervised_ML_Project/env/lib/python3.11/site-packages/pandas/core/indexes/base.py", line 3791, in get_loc
    return self._engine.get_loc(casted_key)
           ^^^^^^^^^^^^^^^^^^^^^^^^^^^^^^^^
  File "index.pyx", line 152, in pandas._libs.index.IndexEngine.get_loc
  File "index.pyx", line 181, in pandas._libs.index.IndexEngine.get_loc
  File "pandas/_libs/hashtable_class_helper.pxi", line 7080, in pandas._libs.hashtable.PyObjectHashTable.get_item
  File "pandas/_libs/hashtable_class_helper.pxi", line 7088, in pandas._libs.hashtable.PyObjectHashTable.get_item
KeyError: 'Cluster'

The above exception was the direct cause of the following exception:

Traceback (most recent call last):
  File "/home/draeghonvm/Projects/Supervised_ML_Project/apps/training/train_model.py", line 69, in training_model
    list_of_clusters = self.X['Cluster'].unique()
                       ~~~~~~^^^^^^^^^^^
  File "/home/draeghonvm/Projects/Supervised_ML_Project/env/lib/python3.11/site-packages/pandas/core/frame.py", line 3893, in __getitem__
    indexer = self.columns.get_loc(key)
              ^^^^^^^^^^^^^^^^^^^^^^^^^
  File "/home/draeghonvm/Projects/Supervised_ML_Project/env/lib/python3.11/site-packages/pandas/core/indexes/base.py", line 3798, in get_loc
    raise KeyError(key) from err
KeyError: 'Cluster'
