2024-01-19 02:52:11,302 : INFO : Start of Training
2024-01-19 02:52:11,302 : INFO : Run_id: 2024-01-19_025211_924841062
2024-01-19 02:52:11,302 : INFO : Start of Data Load, validation and transformation...
2024-01-19 02:52:11,302 : INFO : Start of Archiving Old Rejected Files...
2024-01-19 02:52:11,302 : INFO : End of Archiving Old Rejected Files...
2024-01-19 02:52:11,302 : INFO : Start of Archiving Old Validated Files...
2024-01-19 02:52:11,302 : INFO : End of Archiving Old Validated Files...
2024-01-19 02:52:11,302 : INFO : Start of Archiving Old Processed Files...
2024-01-19 02:52:11,302 : INFO : End of Archiving Old Processed Files...
2024-01-19 02:52:11,303 : INFO : Start of Archiving Old Result Files...
2024-01-19 02:52:11,303 : INFO : End of Archiving Old Result Files...
2024-01-19 02:52:11,303 : INFO : Start of Reading values From Schema...
2024-01-19 02:52:11,304 : INFO : End of Reading values From Schema...
2024-01-19 02:52:11,304 : ERROR : Unsuccessful End of Training
Traceback (most recent call last):
  File "/home/draeghonvm/Projects/Supervised_ML_Project/apps/ingestion/load_validate.py", line 277, in validate_trainset
    column_names, number_of_columns = self.values_from_schema('schema_train')
                                      ^^^^^^^^^^^^^^^^^^^^^^^^^^^^^^^^^^^^^^^
  File "/home/draeghonvm/Projects/Supervised_ML_Project/apps/ingestion/load_validate.py", line 67, in values_from_schema
    return column_names, numer_of_columns
                         ^^^^^^^^^^^^^^^^
NameError: name 'numer_of_columns' is not defined

During handling of the above exception, another exception occurred:

Traceback (most recent call last):
  File "/home/draeghonvm/Projects/Supervised_ML_Project/apps/training/train_model.py", line 58, in training_model
    self.loadValidate.validate_trainset()
  File "/home/draeghonvm/Projects/Supervised_ML_Project/apps/ingestion/load_validate.py", line 294, in validate_trainset
    self.logger('Unsuccessful End of Data Load, validation and transformation')
TypeError: 'Logger' object is not callable
